WARNING (2023-08-02 03:52:43,326): Retrying (Retry(total=4, connect=None, read=None, redirect=None, status=None)) after connection broken by 'ProtocolError('Connection aborted.', FileNotFoundError(2, 'No such file or directory'))': /EQLatest-Monthly/2019/2019_June.html
WARNING (2023-08-02 03:53:03,608): Retrying (Retry(total=3, connect=None, read=None, redirect=None, status=None)) after connection broken by 'ProtocolError('Connection aborted.', RemoteDisconnected('Remote end closed connection without response'))': /EQLatest-Monthly/2019/2019_June.html
WARNING (2023-08-02 03:53:30,359): Retrying (Retry(total=2, connect=None, read=None, redirect=None, status=None)) after connection broken by 'ProtocolError('Connection aborted.', RemoteDisconnected('Remote end closed connection without response'))': /EQLatest-Monthly/2019/2019_June.html
WARNING (2023-08-02 03:53:52,329): Retrying (Retry(total=1, connect=None, read=None, redirect=None, status=None)) after connection broken by 'ProtocolError('Connection aborted.', RemoteDisconnected('Remote end closed connection without response'))': /EQLatest-Monthly/2019/2019_June.html
CRITICAL (2023-08-02 03:53:59,207): <class 'ValueError'>
Length mismatch: Expected axis has 12 elements, new values have 6 elements
['  File "C:\\Users\\AMH-L91\\Documents\\Projects\\phivolcs-bulletins\\phivolcs_bulletin.py", line 132, in <module>\n    df_phv = get_page(sys.argv[1])\n', '  File "C:\\Users\\AMH-L91\\Documents\\Projects\\phivolcs-bulletins\\phivolcs_bulletin.py", line 43, in get_page\n    df_phivolcs.columns = heads\n', '  File "C:\\Users\\AMH-L91\\anaconda3\\envs\\webparse\\lib\\site-packages\\pandas\\core\\generic.py", line 5915, in __setattr__\n    return object.__setattr__(self, name, value)\n', '  File "pandas\\_libs\\properties.pyx", line 69, in pandas._libs.properties.AxisProperty.__set__\n', '  File "C:\\Users\\AMH-L91\\anaconda3\\envs\\webparse\\lib\\site-packages\\pandas\\core\\generic.py", line 823, in _set_axis\n    self._mgr.set_axis(axis, labels)\n', '  File "C:\\Users\\AMH-L91\\anaconda3\\envs\\webparse\\lib\\site-packages\\pandas\\core\\internals\\managers.py", line 230, in set_axis\n    self._validate_set_axis(axis, new_labels)\n', '  File "C:\\Users\\AMH-L91\\anaconda3\\envs\\webparse\\lib\\site-packages\\pandas\\core\\internals\\base.py", line 70, in _validate_set_axis\n    raise ValueError(\n']
